<?xml version="1.0"?>
<robot name="simple_car">

  <!-- Body -->
  <link name="base">
    <visual>
      <geometry>
        <box size="0.3 0.2 0.1"/>
      </geometry>
      <material name="blue">
        <color rgba="0.2 0.3 0.8 1"/>
      </material>
    </visual>
    <collision>
      <geometry>
        <box size="0.3 0.2 0.1"/>
      </geometry>
    </collision>
    <inertial>
      <mass value="1"/>
      <inertia ixx="0.01" iyy="0.01" izz="0.01"/>
    </inertial>
  </link>

  <!-- Left Wheel -->
  <link name="left_wheel">
    <visual>
      <geometry>
        <cylinder radius="0.05" length="0.02"/>
      </geometry>
      <origin rpy="1.5708 0 0" xyz="0 0 0"/>
    </visual>
  </link>

  <!-- Right Wheel -->
  <link name="right_wheel">
    <visual>
      <geometry>
        <cylinder radius="0.05" length="0.02"/>
      </geometry>
      <origin rpy="1.5708 0 0" xyz="0 0 0"/>
    </visual>
  </link>

  <!-- Joints -->
  <joint name="left_joint" type="continuous">
    <parent link="base"/>
    <child link="left_wheel"/>
    <origin xyz="0 -0.12 0" rpy="0 0 0"/>
    <axis xyz="0 1 0"/>
  </joint>

  <joint name="right_joint" type="continuous">
    <parent link="base"/>
    <child link="right_wheel"/>
    <origin xyz="0 0.12 0" rpy="0 0 0"/>
    <axis xyz="0 1 0"/>
  </joint>

</robot>
